F.
======================================================================
FAIL: test_Fail (__main__.TestCase)
----------------------------------------------------------------------
Traceback (most recent call last):
  File "test.py", line 21, in test_Fail
    assert 'Goodbye, World!' in rv.data
AssertionError

----------------------------------------------------------------------
Ran 2 tests in 0.025s

FAILED (failures=1)
